participant ID:  FLT04 MNI152NLin2009cAsym 
first-level FWHM:  1.50 
desired searchlight radius (in voxels):  5
loading stimulus dissimilarity matrices
Traceback (most recent call last):
  File "/bgfs/bchandrasekaran/krs228/software/miniconda3/envs/py3/lib/python3.9/site-packages/pandas/core/indexes/base.py", line 3080, in get_loc
    return self._engine.get_loc(casted_key)
  File "pandas/_libs/index.pyx", line 70, in pandas._libs.index.IndexEngine.get_loc
  File "pandas/_libs/index.pyx", line 101, in pandas._libs.index.IndexEngine.get_loc
  File "pandas/_libs/hashtable_class_helper.pxi", line 1625, in pandas._libs.hashtable.Int64HashTable.get_item
  File "pandas/_libs/hashtable_class_helper.pxi", line 1632, in pandas._libs.hashtable.Int64HashTable.get_item
KeyError: 0

The above exception was the direct cause of the following exception:

Traceback (most recent call last):
  File "/ihome/bchandrasekaran/krs228/software/FLT/rsa/rsa_searchlight.py", line 208, in <module>
    ffr_id = participants_df['FFR_id'].loc[participants_df['participant_id'] == 'sub-'+sub_id][0]
  File "/bgfs/bchandrasekaran/krs228/software/miniconda3/envs/py3/lib/python3.9/site-packages/pandas/core/series.py", line 853, in __getitem__
    return self._get_value(key)
  File "/bgfs/bchandrasekaran/krs228/software/miniconda3/envs/py3/lib/python3.9/site-packages/pandas/core/series.py", line 961, in _get_value
    loc = self.index.get_loc(label)
  File "/bgfs/bchandrasekaran/krs228/software/miniconda3/envs/py3/lib/python3.9/site-packages/pandas/core/indexes/base.py", line 3082, in get_loc
    raise KeyError(key) from err
KeyError: 0
